Workbook

Sheet Analysis
A3: Row Labels | B3: Count of magType
A4: mb | B4: 4
A5: md | B5: 2
A6: Mi | B6: 5
A7: ml | B7: 1
A8: ms | B8: 3
A9: mw | B9: 51
A10: mwb | B10: 100
A11: mwc | B11: 332
A12: mww | B12: 502
A13: Grand Total | B13: 1000

Sheet Alert
A3: Row Labels | B3: Count of title
A4: green | B4: 353
A5: orange | B5: 24
A6: red | B6: 13
A7: yellow | B7: 59
A8: (blank) | B8: 551
A9: Grand Total | B9: 1000

Sheet Magtype
A3: Row Labels | B3: Count of magType_lower
A4: mb | B4: 4
A5: md | B5: 2
A6: mi | B6: 5
A7: ml | B7: 1
A8: ms | B8: 3
A9: mw | B9: 51
A10: mwb | B10: 100
A11: mwc | B11: 332
A12: mww | B12: 502
A13: Grand Total | B13: 1000

Sheet Earthquake Events by year
A1: Earthquake Events by Year
A2: Year | B2: Count of title
A3: 1995 | B3: 29
A4: 1996 | B4: 35
A5: 1997 | B5: 28
A6: 1998 | B6: 23
A7: 1999 | B7: 33
A8: 2000 | B8: 35
A9: 2001 | B9: 28
A10: 2002 | B10: 25
A11: 2003 | B11: 31
A12: 2004 | B12: 32
A13: 2005 | B13: 28
A14: 2006 | B14: 26
... A31: 2023 | B31: 34
A32: Grand Total | B32: 1000

Sheet earthquake_1995-2023
A1: title | B1: magnitude | C1: date_time | D1: cdi | E1: mmi | F1: alert | G1: tsunami | H1: sig | I1: net | J1: nst | K1: dmin | L1: gap | M1: magType | N1: depth | O1: latitude | P1: longitude | Q1: location | R1: continent | S1: country | T1: Column1 | U1: title_pattern | V1: magType_lower | W1: duplicate_flag | X1: Year
A2: M 6.5 - 42 km W of Sola, Vanuatu | B2: 6.5 | C2: 45154.533 | D2: 7 | E2: 4 | F2: green | G2: 0 | H2: 657 | I2: us | J2: 114 | K2: 7.177 | L2: 25 | M2: mww | N2: 192.955 | O2: -13.8814 | P2: 167.158 | Q2: Sola, Vanuatu | S2: Vanuatu | U2: =IF(ISNUMBER(SEARCH("km",A2)),"N km direction of city","Named-region") -> N km direction of city | V2: =LOWER(M2) -> mww | W2: =COUNTIFS($A$2:$A$1001,A2,$C$2:$C$1001,C2)>1 -> FALSE | X2: =YEAR(C2) -> 2023
A3: M 6.5 - 43 km S of IntipucÃ¡, El Salvador | B3: 6.5 | C3: 45126.015 | D3: 8 | E3: 6 | F3: yellow | G3: 0 | H3: 775 | I3: us | J3: 92 | K3: 0.679 | L3: 40 | M3: mww | N3: 69.727 | O3: 12.814 | P3: -88.1265 | Q3: IntipucÃ¡, El Salvador | U3: =IF(ISNUMBER(SEARCH("km",A3)),"N km direction of city","Named-region") -> N km direction of city | V3: =LOWER(M3) -> mww | X3: =YEAR(C3) -> 2023
A4: M 6.6 - 25 km ESE of LoncopuÃ©, Argentina | B4: 6.6 | C4: 45124.128 | D4: 7 | E4: 5 | F4: green | G4: 0 | H4: 899 | I4: us | J4: 70 | K4: 1.634 | L4: 28 | M4: mww | N4: 171.371 | O4: -38.1911 | P4: -70.3731 | Q4: LoncopuÃ©, Argentina | R4: South America | S4: Argentina | U4: =IF(ISNUMBER(SEARCH("km",A4)),"N km direction of city","Named-region") -> N km direction of city | V4: =LOWER(M4) -> mww | X4: =YEAR(C4) -> 2023
A5: M 7.2 - 98 km S of Sand Point, Alaska | B5: 7.2 | C5: 45123.283 | D5: 6 | E5: 6 | F5: green | G5: 1 | H5: 860 | I5: us | J5: 173 | K5: 0.907 | L5: 36 | M5: mww | N5: 32.571 | O5: 54.3844 | P5: -160.699 | Q5: Sand Point, Alaska | U5: =IF(ISNUMBER(SEARCH("km",A5)),"N km direction of city","Named-region") -> N km direction of city | V5: =LOWER(M5) -> mww | X5: =YEAR(C5) -> 2023
A6: M 7.3 - Alaska Peninsula | B6: 7.3 | C6: 45123.283 | D6: 0 | E6: 5 | G6: 1 | H6: 820 | I6: at | J6: 79 | K6: 0.879451 | L6: 172.8 | M6: Mi | N6: 21 | O6: 54.49 | P6: -160.796 | Q6: Alaska Peninsula | U6: =IF(ISNUMBER(SEARCH("km",A6)),"N km direction of city","Named-region") -> Named-region | V6: =LOWER(M6) -> mi | X6: =YEAR(C6) -> 2023
A7: M 6.6 - 277 km NNE of Codrington, Antigua and Barbuda | B7: 6.6 | C7: 45117.853 | D7: 5 | E7: 4 | F7: green | G7: 1 | H7: 802 | I7: us | J7: 95 | K7: 2.454 | L7: 37 | M7: mww | N7: 10 | O7: 20.0196 | P7: -61.0955 | Q7: Codrington, Antigua and Barbuda | U7: =IF(ISNUMBER(SEARCH("km",A7)),"N km direction of city","Named-region") -> N km direction of city | V7: =LOWER(M7) -> mww | X7: =YEAR(C7) -> 2023
A8: M 6.9 - Tonga | B8: 6.9 | C8: 45109.435 | D8: 4 | E8: 4 | F8: green | G8: 1 | H8: 741 | I8: us | J8: 136 | K8: 1.179 | L8: 23 | M8: mww | N8: 229 | O8: -17.853 | P8: -174.937 | Q8: Tonga | U8: =IF(ISNUMBER(SEARCH("km",A8)),"N km direction of city","Named-region") -> Named-region | V8: =LOWER(M8) -> mww | X8: =YEAR(C8) -> 2023
A9: M 7.2 - south of the Fiji Islands | B9: 7.2 | C9: 45092.754 | D9: 8 | E9: 6 | F9: green | G9: 1 | H9: 804 | I9: us | J9: 85 | K9: 2.59 | L9: 24 | M9: mww | N9: 167.404 | O9: -22.9824 | P9: -177.208 | Q9: the Fiji Islands | U9: =IF(ISNUMBER(SEARCH("km",A9)),"N km direction of city","Named-region") -> Named-region | V9: =LOWER(M9) -> mww | X9: =YEAR(C9) -> 2023
A10: M 6.6 - Panama-Colombia border region | B10: 6.6 | C10: 45071.128 | D10: 6 | E10: 6 | F10: green | G10: 1 | H10: 733 | I10: us | J10: 50 | K10: 2.163 | L10: 129 | M10: mww | N10: 10 | O10: 8.8894 | P10: -77.1231 | Q10: Panama-Colombia border region | S10: Colombia | U10: =IF(ISNUMBER(SEARCH("km",A10)),"N km direction of city","Named-region") -> Named-region | V10: =LOWER(M10) -> mww | X10: =YEAR(C10) -> 2023
A11: M 7.1 - southeast of the Loyalty Islands | B11: 7.1 | C11: 45066.077 | D11: 3 | E11: 4 | F11: green | G11: 1 | H11: 777 | I11: us | J11: 98 | K11: 2.812 | L11: 56 | M11: mww | N11: 35.981 | O11: -23.0622 | P11: 170.456 | Q11: the Loyalty Islands | U11: =IF(ISNUMBER(SEARCH("km",A11)),"N km direction of city","Named-region") -> Named-region | V11: =LOWER(M11) -> mww | X11: =YEAR(C11) -> 2023
A12: M 7.7 - southeast of the Loyalty Islands | B12: 7.7 | C12: 45065.123 | D12: 5 | E12: 4 | F12: green | G12: 1 | H12: 927 | I12: us | J12: 277 | K12: 3.111 | L12: 15 | M12: mww | N12: 18.027 | O12: -23.2286 | P12: 170.694 | Q12: the Loyalty Islands | U12: =IF(ISNUMBER(SEARCH("km",A12)),"N km direction of city","Named-region") -> Named-region | V12: =LOWER(M12) -> mww | X12: =YEAR(C12) -> 2023
A13: M 7.6 - 95 km WNW of Hihifo, Tonga | B13: 7.6 | C13: 45056.668 | D13: 8 | E13: 6 | F13: green | G13: 1 | H13: 907 | I13: us | J13: 111 | K13: 3.631 | L13: 17 | M13: mww | N13: 210.097 | O13: -15.6002 | P13: -174.608 | Q13: Hihifo, Tonga | U13: =IF(ISNUMBER(SEARCH("km",A13)),"N km direction of city","Named-region") -> N km direction of city | V13: =LOWER(M13) -> mww | X13: =YEAR(C13) -> 2023
A14: M 6.6 - south of the Fiji Islands | B14: 6.6 | C14: 45044.134 | D14: 0 | E14: 2 | F14: green | G14: 0 | H14: 670 | I14: us | J14: 52 | K14: 5.123 | L14: 50 | M14: mww | N14: 598.467 | O14: -25.2657 | P14: 178.424 | Q14: the Fiji Islands | U14: =IF(ISNUMBER(SEARCH("km",A14)),"N km direction of city","Named-region") -> Named-region | V14: =LOWER(M14) -> mww | X14: =YEAR(C14) -> 2023
A15: M 7.1 - 170 km SSE of Teluk Dalam, Indonesia | B15: 7.1 | C15: 45040.833 | D15: 9 | E15: 7 | F15: green | G15: 0 | H15: 838 | I15: us | J15: 70 | K15: 2.282 | L15: 58 | M15: mww | N15: 15.462 | O15: -0.781 | P15: 98.5339 | Q15: Teluk Dalam, Indonesia | S15: Indonesia | U15: =IF(ISNUMBER(SEARCH("km",A15)),"N km direction of city","Named-region") -> N km direction of city | V15: =LOWER(M15) -> mww | X15: =YEAR(C15) -> 2023
A16: M 7.1 - Kermadec Islands, New Zealand | B16: 7.1 | C16: 45040.028 | D16: 8 | E16: 7 | F16: green | G16: 1 | H16: 777 | I16: us | J16: 126 | K16: 0.708 | L16: 23 | M16: mww | N16: 43.063 | O16: -30.0249 | P16: -177.897 | Q16: Kermadec Islands, New Zealand | U16: =IF(ISNUMBER(SEARCH("km",A16)),"N km direction of city","Named-region") -> Named-region | V16: =LOWER(M16) -> mww | X16: =YEAR(C16) -> 2023
A17: M 6.7 - south of the Fiji Islands | B17: 6.7 | C17: 45034.188 | D17: 0 | E17: 3 | F17: green | G17: 1 | H17: 691 | I17: us | J17: 166 | K17: 4.719 | L17: 10 | M17: mww | N17: 595.854 | O17: -22.2844 | P17: 179.391 | Q17: the Fiji Islands | U17: =IF(ISNUMBER(SEARCH("km",A17)),"N km direction of city","Named-region") -> Named-region | V17: =LOWER(M17) -> mww | X17: =YEAR(C17) -> 2023
A18: M 7.0 - 96 km N of Tuban, Indonesia | B18: 7 | C18: 45030.413 | D18: 5 | E18: 3 | F18: green | G18: 0 | H18: 818 | I18: us | J18: 131 | K18: 1.881 | L18: 31 | M18: mww | N18: 594.028 | O18: -6.0255 | P18: 112.033 | Q18: Tuban, Indonesia | S18: Indonesia | U18: =IF(ISNUMBER(SEARCH("km",A18)),"N km direction of city","Named-region") -> N km direction of city | V18: =LOWER(M18) -> mww | X18: =YEAR(C18) -> 2023
A19: M 6.5 - near the east coast of the Kamchatka Peninsula, Russia | B19: 6.5 | C19: 45019.129 | D19: 7 | E19: 6 | F19: yellow | G19: 1 | H19: 655 | I19: us | J19: 104 | K19: 0.266 | L19: 30 | M19: mww | N19: 105.631 | O19: 52.7772 | P19: 158.484 | Q19: the Kamchatka Peninsula, Russia | R19: Asia | S19: Russian Federation (the) | U19: =IF(ISNUMBER(SEARCH("km",A19)),"N km direction of city","Named-region") -> Named-region | V19: =LOWER(M19) -> mww | X19: =YEAR(C19) -> 2023
A20: M 7.0 - New Guinea, Papua New Guinea | B20: 7 | C20: 45018.753 | D20: 7 | E20: 7 | F20: green | G20: 1 | H20: 781 | I20: us | J20: 105 | K20: 6.45 | L20: 31 | M20: mww | N20: 62.603 | O20: -4.2924 | P20: 143.155 | Q20: New Guinea, Papua New Guinea | R20: Asia | S20: Papua New Guinea | U20: =IF(ISNUMBER(SEARCH("km",A20)),"N km direction of city","Named-region") -> Named-region | V20: =LOWER(M20) -> mww | X20: =YEAR(C20) -> 2023
A21: M 6.5 - 84 km NNW of San Antonio de los Cobres, Argentina | B21: 6.5 | C21: 45007.667 | D21: 4 | E21: 4 | F21: green | G21: 0 | H21: 656 | I21: us | J21: 97 | K21: 1.622 | L21: 33 | M21: mww | N21: 209.976 | O21: -23.4797 | P21: -66.5108 | Q21: San Antonio de los Cobres, Argentina | R21: South America | S21: Argentina | U21: =IF(ISNUMBER(SEARCH("km",A21)),"N km direction of city","Named-region") -> N km direction of city | V21: =LOWER(M21) -> mww | X21: =YEAR(C21) -> 2023
A22: M 6.5 - 40 km SSE of Jurm, Afghanistan | B22: 6.5 | C22: 45006.699 | D22: 7 | E22: 5 | F22: green | G22: 0 | H22: 1350 | I22: us | J22: 134 | K22: 2.53 | L22: 13 | M22: mww | N22: 187.589 | O22: 36.5227 | P22: 70.9787 | Q22: Jurm, Afghanistan | R22: Asia | S22: Afghanistan | U22: =IF(ISNUMBER(SEARCH("km",A22)),"N km direction of city","Named-region") -> N km direction of city | V22: =LOWER(M22) -> mww | X22: =YEAR(C22) -> 2023
A23: M 6.8 - near the coast of Ecuador | B23: 6.8 | C23: 45003.717 | D23: 9 | E23: 7 | F23: orange | G23: 1 | H23: 1159 | I23: us | J23: 152 | K23: 0.709 | L23: 28 | M23: mww | N23: 65.842 | O23: -2.851 | P23: -79.8001 | Q23: Ecuador | R23: South America | S23: Ecuador | U23: =IF(ISNUMBER(SEARCH("km",A23)),"N km direction of city","Named-region") -> Named-region | V23: =LOWER(M23) -> mww | X23: =YEAR(C23) -> 2023
A24: M 7.0 - Kermadec Islands region | B24: 7 | C24: 45001.039 | D24: 8 | E24: 5 | F24: green | G24: 1 | H24: 756 | I24: us | J24: 116 | K24: 1.789 | L24: 22 | M24: mww | N24: 22.065 | O24: -30.1147 | P24: -176.112 | Q24: Kermadec Islands region | U24: =IF(ISNUMBER(SEARCH("km",A24)),"N km direction of city","Named-region") -> Named-region | V24: =LOWER(M24) -> mww | X24: =YEAR(C24) -> 2023
A25: M 6.9 - Kermadec Islands, New Zealand | B25: 6.9 | C25: 44989.278 | D25: 5 | E25: 5 | F25: green | G25: 1 | H25: 735 | I25: us | J25: 108 | K25: 0.784 | L25: 18 | M25: mww | N25: 205.681 | O25: -29.4748 | P25: -178.787 | Q25: Kermadec Islands, New Zealand | U25: =IF(ISNUMBER(SEARCH("km",A25)),"N km direction of city","Named-region") -> Named-region | V25: =LOWER(M25) -> mww | X25: =YEAR(C25) -> 2023
A26: M 6.5 - 86 km WSW of Port-Olry, Vanuatu | B26: 6.5 | C26: 44987.753 | D26: 7 | E26: 6 | F26: green | G26: 1 | H26: 653 | I26: us | J26: 66 | K26: 5.483 | L26: 45 | M26: mww | N26: 10 | O26: -15.3597 | P26: 166.385 | Q26: Port-Olry, Vanuatu | U26: =IF(ISNUMBER(SEARCH("km",A26)),"N km direction of city","Named-region") -> N km direction of city | V26: =LOWER(M26) -> mww | X26: =YEAR(C26) -> 2023
A27: M 6.5 - 108 km NW of Kimbe, Papua New Guinea | B27: 6.5 | C27: 44986.233 | D27: 4 | E27: 2 | F27: green | G27: 1 | H27: 652 | I27: us | J27: 115 | K27: 2.739 | L27: 20 | M27: mww | N27: 598.925 | O27: -4.8138 | P27: 149.487 | Q27: Kimbe, Papua New Guinea | S27: Papua New Guinea | U27: =IF(ISNUMBER(SEARCH("km",A27)),"N km direction of city","Named-region") -> N km direction of city | V27: =LOWER(M27) -> mww | X27: =YEAR(C27) -> 2023
A28: M 6.8 - 67 km W of Murghob, Tajikistan | B28: 6.8 | C28: 44980.026 | D28: 9 | E28: 7 | F28: green | G28: 0 | H28: 737 | I28: us | J28: 128 | K28: 1.783 | L28: 20 | M28: mww | N28: 20.522 | O28: 38.0726 | P28: 73.2077 | Q28: Murghob, Tajikistan | R28: Asia | S28: Tajikistan | U28: =IF(ISNUMBER(SEARCH("km",A28)),"N km direction of city","Named-region") -> N km direction of city | V28: =LOWER(M28) -> mww | X28: =YEAR(C28) -> 2023
A29: M 7.5 - 4 km SSE of EkinÃ¶zÃ¼, Turkey | B29: 7.5 | C29: 44963.433 | D29: 9 | E29: 9 | F29: orange | G29: 0 | H29: 1411 | I29: us | J29: 135 | K29: 0.85 | L29: 17 | M29: mww | N29: 10 | O29: 38.0235 | P29: 37.203 | Q29: EkinÃ¶zÃ¼, Turkey | R29: Asia | S29: Turkiye | U29: =IF(ISNUMBER(SEARCH("km",A29)),"N km direction of city","Named-region") -> N km direction of city | V29: =LOWER(M29) -> mww | X29: =YEAR(C29) -> 2023
A30: M 6.7 - 18 km ESE of NurdaÄŸÄ±, Turkey | B30: 6.7 | C30: 44963.061 | D30: 9 | E30: 8 | F30: yellow | G30: 0 | H30: 800 | I30: us | J30: 108 | K30: 0.218 | L30: 44 | M30: mww | N30: 14.497 | O30: 37.4135 | P30: 36.8306 | Q30: NurdaÄŸÄ±, Turkey | R30: Asia | S30: Turkiye | U30: =IF(ISNUMBER(SEARCH("km",A30)),"N km direction of city","Named-region") -> N km direction of city | V30: =LOWER(M30) -> mww | X30: =YEAR(C30) -> 2023
A31: M 7.8 - Central Turkey | B31: 7.8 | C31: 44963.053 | D31: 9 | E31: 9 | F31: red | G31: 0 | H31: 2910 | I31: us | J31: 118 | K31: 1.919 | L31: 32 | M31: mww | N31: 17.925 | O31: 37.2012 | P31: 36.9997 | Q31: Central Turkey | R31: Asia | S31: Turkiye | U31: =IF(ISNUMBER(SEARCH("km",A31)),"N km direction of city","Named-region") -> Named-region | V31: =LOWER(M31) -> mww | X31: =YEAR(C31) -> 2023
A32: M 6.8 - | B32: 6.8 | C32: 44946.923 | D32: 4 | E32: 3 | F32: green | G32: 0 | H32: 718 | I32: us | J32: 60 | K32: 5.129 | L32: 61 | M32: mww | N32: 610.671 | O32: -26.7209 | P32: -63.0394 | R32: South America | S32: Argentina | U32: =IF(ISNUMBER(SEARCH("km",A32)),"N km direction of city","Named-region") -> Named-region | V32: =LOWER(M32) -> mww | X32: =YEAR(C32) -> 2023
A33: M 7.0 - 153 km NW of Tobelo, Indonesia | B33: 7 | C33: 44944.254 | D33: 3 | E33: 5 | F33: green | G33: 1 | H33: 756 | I33: us | J33: 130 | K33: 1.974 | L33: 17 | M33: mwc | N33: 28.566 | O33: 2.7401 | P33: 127.051 | Q33: Tobelo, Indonesia | S33: Indonesia | U33: =IF(ISNUMBER(SEARCH("km",A33)),"N km direction of city","Named-region") -> N km direction of city | V33: =LOWER(M33) -> mwc | X33: =YEAR(C33) -> 2023
A34: M 7.6 - Pulau Pulau Tanimbar, Indonesia | B34: 7.6 | C34: 44935.741 | D34: 5 | E34: 7 | F34: green | G34: 0 | H34: 957 | I34: us | J34: 114 | K34: 1.575 | L34: 21 | M34: mww | N34: 105.249 | O34: -7.0852 | P34: 130.039 | Q34: Pulau Pulau Tanimbar, Indonesia | S34: Indonesia | U34: =IF(ISNUMBER(SEARCH("km",A34)),"N km direction of city","Named-region") -> Named-region | V34: =LOWER(M34) -> mww | X34: =YEAR(C34) -> 2023
A35: M 7.0 - Vanuatu | B35: 7 | C35: 44934.522 | D35: 8 | E35: 7 | F35: green | G35: 1 | H35: 768 | I35: us | J35: 116 | K35: 6.096 | L35: 36 | M35: mww | N35: 29 | O35: -14.9383 | P35: 166.878 | Q35: Vanuatu | S35: Vanuatu | U35: =IF(ISNUMBER(SEARCH("km",A35)),"N km direction of city","Named-region") -> Named-region | V35: =LOWER(M35) -> mww | X35: =YEAR(C35) -> 2023
A36: M 6.8 - 109 km NE of Hihifo, Tonga | B36: 6.8 | C36: 44899.808 | D36: 5 | E36: 5 | F36: green | G36: 1 | H36: 720 | I36: us | J36: 152 | K36: 2.587 | L36: 26 | M36: mww | N36: 38 | O36: -15.3983 | P36: -172.968 | Q36: Hihifo, Tonga | U36: =IF(ISNUMBER(SEARCH("km",A36)),"N km direction of city","Named-region") -> N km direction of city | V36: =LOWER(M36) -> mww | X36: =YEAR(C36) -> 2022
A37: M 7.0 - 18 km SW of Malango, Solomon Islands | B37: 7 | C37: 44887.085 | D37: 8 | E37: 7 | F37: green | G37: 1 | H37: 768 | I37: us | J37: 117 | K37: 0.509 | L37: 17 | M37: mww | N37: 14 | O37: -9.7963 | P37: 159.596 | Q37: Malango, Solomon Islands | R37: Oceania | S37: Solomon Islands | U37: =IF(ISNUMBER(SEARCH("km",A37)),"N km direction of city","Named-region") -> N km direction of city | V37: =LOWER(M37) -> mww | X37: =YEAR(C37) -> 2022
A38: M 6.9 - 204 km SW of Bengkulu, Indonesia | B38: 6.9 | C38: 44883.567 | D38: 4 | E38: 4 | F38: green | G38: 0 | H38: 735 | I38: us | J38: 99 | K38: 2.229 | L38: 34 | M38: mww | N38: 25 | O38: -4.9559 | P38: 100.738 | Q38: Bengkulu, Indonesia | U38: =IF(ISNUMBER(SEARCH("km",A38)),"N km direction of city","Named-region") -> N km direction of city | V38: =LOWER(M38) -> mww | X38: =YEAR(C38) -> 2022
A39: M 7.0 - | B39: 7 | C39: 44877.298 | D39: 3 | E39: 3 | F39: green | G39: 1 | H39: 755 | I39: us | J39: 147 | K39: 3.125 | L39: 18 | M39: mww | N39: 579 | O39: -20.0508 | P39: -178.346 | R39: Oceania | S39: Fiji | U39: =IF(ISNUMBER(SEARCH("km",A39)),"N km direction of city","Named-region") -> Named-region | V39: =LOWER(M39) -> mww | X39: =YEAR(C39) -> 2022
A40: M 7.3 - 205 km ESE of Neiafu, Tonga | B40: 7.3 | C40: 44876.45 | D40: 5 | E40: 5 | F40: green | G40: 1 | H40: 833 | I40: us | J40: 149 | K40: 1.865 | L40: 21 | M40: mww | N40: 37 | O40: -19.2918 | P40: -172.129 | Q40: Neiafu, Tonga | U40: =IF(ISNUMBER(SEARCH("km",A40)),"N km direction of city","Named-region") -> N km direction of city | V40: =LOWER(M40) -> mww | X40: =YEAR(C40) -> 2022
...

Sheet Summary
A1: EARTHQUAKE DATASET SUMMARY | J1: Cell | K1: Enter | T1: Magnitude check
A2: Missing alert values | B2: 55.1% blank | C2: Replace blanks with "Unknown" or another explicit missing category; do not invent alert levels. | J2: E2 | K2: Column | T2: =ISNUMBER(VALUE(B2)) -> FALSE
A3: Number of Records | B3: =COUNTA('earthquake_1995-2023'!B:B)-1 -> 1000 | D3: magType | E3: Count | G3: Alert Level | H3: Count | J3: F2 | K3: Data Type
A4: Blank Magnitude Values | B4: =COUNTBLANK('earthquake_1995-2023'!B2:B1001) -> 0 | D4: {=_xlfn.UNIQUE('earthquake_1995-2023'!M2:M1001)} -> mww | E4: =COUNTIF('earthquake_1995-2023'!M$2:M$1001,D4) -> 502 | G4: green | H4: =COUNTIF('earthquake_1995-2023'!F$2:F$1001,G4) -> 353 | J4: E | K4: F
A5: Minimum Magnitude | B5: =MIN('earthquake_1995-2023'!B2:B1001) -> 6.5 | D5: Mi | E5: =COUNTIF('earthquake_1995-2023'!M$2:M$1001,D5) -> 5 | G5: yellow | H5: =COUNTIF('earthquake_1995-2023'!F$2:F$1001,G5) -> 59 | J5: title | K5: Text
A6: Maximum Magnitude | B6: =MAX('earthquake_1995-2023'!B2:B1001) -> 9.1 | D6: mwc | E6: =COUNTIF('earthquake_1995-2023'!M$2:M$1001,D6) -> 332 | G6: orange | H6: =COUNTIF('earthquake_1995-2023'!F$2:F$1001,G6) -> 24 | J6: magnitude | K6: Numeric
A7: Average Magnitude | B7: =AVERAGE('earthquake_1995-2023'!B2:B1001) -> 6.94015 | D7: mwb | E7: =COUNTIF('earthquake_1995-2023'!M$2:M$1001,D7) -> 100 | G7: red | H7: =COUNTIF('earthquake_1995-2023'!F$2:F$1001,G7) -> 13 | J7: date_time | K7: Datetime
A8: Minimum Depth | B8: =MIN('earthquake_1995-2023'!N2:N1001) -> 2.7 | D8: ml | E8: =COUNTIF('earthquake_1995-2023'!M$2:M$1001,D8) -> 1 | J8: cdi | K8: Numeric
A9: Maximum Depth | B9: =MAX('earthquake_1995-2023'!N2:N1001) -> 670.81 | D9: mw | E9: =COUNTIF('earthquake_1995-2023'!M$2:M$1001,D9) -> 51 | J9: mmi | K9: Numeric
A10: Average Depth | B10: =AVERAGE('earthquake_1995-2023'!N2:N1001) -> 74.612541 | D10: ms | E10: =COUNTIF('earthquake_1995-2023'!M$2:M$1001,D10) -> 3 | J10: alert | K10: Categorical
D11: mb | E11: =COUNTIF('earthquake_1995-2023'!M$2:M$1001,D11) -> 4 | J11: tsunami | K11: Categorical
D12: md | E12: =COUNTIF('earthquake_1995-2023'!M$2:M$1001,D12) -> 2 | J12: sig | K12: Numeric
J13: net | K13: Categorical
A14: Missing Value Check | J14: nst | K14: Numeric
A15: Field | B15: Blank Count | C15: Blank Percentage | J15: dmin | K15: Numeric
A16: alert | B16: =COUNTBLANK('earthquake_1995-2023'!F2:F1001) -> 551 | C16: =B16/1000 -> 0.551 | J16: gap | K16: Numeric
A17: continent | B17: =COUNTBLANK('earthquake_1995-2023'!R2:R1001) -> 716 | C17: =B17/1000 -> 0.716 | J17: magType | K17: Categorical
A18: country | B18: =COUNTBLANK('earthquake_1995-2023'!S2:S1001) -> 349 | C18: =B18/1000 -> 0.349 | J18: depth | K18: Numeric
A19: location | B19: =COUNTBLANK('earthquake_1995-2023'!Q2:Q1001) -> 6 | C19: =B19/1000 -> 0.006 | J19: latitude | K19: Numeric
J20: longitude | K20: Numeric
J21: location | K21: Text
A22: Raw date_time check | B22: =ISNUMBER('earthquake_1995-2023'!C2) -> TRUE | J22: continent | K22: Categorical
A23: Is date_time text? | B23: =ISTEXT('earthquake_1995-2023'!C2) -> FALSE | J23: country | K23: Categorical
A25: Title Pattern | B25: Count
A26: N km direction of city | B26: =COUNTIF('earthquake_1995-2023'!U2:U1001,"N km direction of city") -> 870
A27: Named-region | B27: =COUNTIF('earthquake_1995-2023'!U2:U1001,"Named-region") -> 130
A29: Duplicate Rows | B29: =COUNTIF('earthquake_1995-2023'!W2:W1001,TRUE) -> 0

Sheet Data quality Summary
A1: Data Quality Issue | B1: Evidence / Result | C1: Lab 4 Fix
A2: Missing alert values | B2: 55.1% blank | C2: Replace blanks with Unknown
A3: Missing continent values | B3: 71.6% blank | C3: Derive where possible; otherwise Unknown
A4: Missing country values | B4: 34.9% blank | C4: Derive where possible; otherwise Unknown
A5: Missing location values | B5: 0.6% blank | C5: Recover where possible; otherwise Unknown
A6: Mixed title formats | B6: 870 distance/direction, 130 named-region | C6: Handle the two formats separately
A7: Inconsistent magType casing | B7: Mi → mi | C7: Convert magType to lowercase
A8: Duplicate events | B8: 0 duplicate rows | C8: Check and remove confirmed duplicates
A9: date_time type | B9: Excel recognizes it as Date/Time | C9: Keep as true Excel datetime

Sheet Dashboard
A1: Earthquake Data Analysis Dashboard
A3: Total Earthquake Records | C3: Average Magnitude | E3: Minimum Magnitude | G3: Maximum Magnitude
A4: =COUNTA('earthquake_1995-2023'!A2:A1001) -> 1000 | C4: =AVERAGE('earthquake_1995-2023'!B2:B1001) -> 6.94015 | E4: =MIN('earthquake_1995-2023'!B2:B1001) -> 6.5 | G4: =MAX('earthquake_1995-2023'!B2:B1001) -> 9.1
A6: Average Depth | C6: Minimum Depth | E6: Maximum Depth | G6: Blank Alert %
A7: =AVERAGE('earthquake_1995-2023'!N2:N1001) -> 74.612541 | C7: =MIN('earthquake_1995-2023'!N2:N1001) -> 2.7 | E7: =MAX('earthquake_1995-2023'!N2:N1001) -> 670.81 | G7: =COUNTBLANK('earthquake_1995-2023'!F2:F1001)/COUNTA('earthquake_1995-2023'!A2:A1001) -> 0.551
A10: Row Labels | B10: Count of magType
A11: mb | B11: 4
A12: md | B12: 2
A13: Mi | B13: 5
A14: ml | B14: 1
A15: ms | B15: 3
A16: mw | B16: 51
A17: mwb | B17: 100
A18: mwc | B18: 332
A19: mww | B19: 502
A27: Row Labels | B27: Count of title
A28: green | B28: 353
A29: orange | B29: 24
A30: red | B30: 13
A31: yellow | B31: 59
A32: (blank) | B32: 551
A43: Annual Trend
